{
    "cve": {
        "data_type": "CVE",
        "data_format": "MITRE",
        "data_version": "4.0",
        "CVE_data_meta": {
            "ID": "CVE-2019-4614",
            "ASSIGNER": "cve@mitre.org"
        },
        "problemtype": {
            "problemtype_data": [
                {
                    "description": []
                }
            ]
        },
        "references": {
            "reference_data": [
                {
                    "url": "https:\/\/exchange.xforce.ibmcloud.com\/vulnerabilities\/168639",
                    "name": "ibm-mq-cve20194614-dos (168639)",
                    "refsource": "XF",
                    "tags": []
                },
                {
                    "url": "https:\/\/www.ibm.com\/support\/pages\/node\/1106523",
                    "name": "https:\/\/www.ibm.com\/support\/pages\/node\/1106523",
                    "refsource": "CONFIRM",
                    "tags": []
                }
            ]
        },
        "description": {
            "description_data": [
                {
                    "lang": "en",
                    "value": "IBM MQ and IBM MQ Appliance 8.0 and 9.0 LTS client connecting to a Queue Manager could cause a SIGSEGV denial of service caused by converting an invalid message. IBM X-Force ID: 168639."
                }
            ]
        }
    },
    "configurations": {
        "CVE_data_version": "4.0",
        "nodes": []
    },
    "impact": [],
    "publishedDate": "2020-01-28T19:15Z",
    "lastModifiedDate": "2020-01-28T19:39Z"
}