{
    "cve": {
        "data_type": "CVE",
        "data_format": "MITRE",
        "data_version": "4.0",
        "CVE_data_meta": {
            "ID": "CVE-2020-1738",
            "ASSIGNER": "cve@mitre.org"
        },
        "problemtype": {
            "problemtype_data": [
                {
                    "description": []
                }
            ]
        },
        "references": {
            "reference_data": [
                {
                    "url": "https:\/\/bugzilla.redhat.com\/show_bug.cgi?id=CVE-2020-1738",
                    "name": "https:\/\/bugzilla.redhat.com\/show_bug.cgi?id=CVE-2020-1738",
                    "refsource": "CONFIRM",
                    "tags": []
                },
                {
                    "url": "https:\/\/github.com\/ansible\/ansible\/issues\/67796",
                    "name": "https:\/\/github.com\/ansible\/ansible\/issues\/67796",
                    "refsource": "CONFIRM",
                    "tags": []
                }
            ]
        },
        "description": {
            "description_data": [
                {
                    "lang": "en",
                    "value": "A flaw was found in Ansible Engine when the module package or service is used and the parameter 'use' is not specified. If a previous task is executed with a malicious user, the module sent can be selected by the attacker using the ansible facts file. All versions in 2.7.x, 2.8.x and 2.9.x branches are believed to be vulnerable."
                }
            ]
        }
    },
    "configurations": {
        "CVE_data_version": "4.0",
        "nodes": []
    },
    "impact": [],
    "publishedDate": "2020-03-16T16:15Z",
    "lastModifiedDate": "2020-03-16T17:19Z"
}